Workbook

Sheet 資本門
A1: 資本門款項
A2: 發票開立日期 | B2: 發票號碼 | C2: 品名 | D2: 數量 | E2: 單價 | F2: 總計 (含稅) | G2: 核銷單列印日期 | H2: 核銷案號 | I2: 說明 / 備註
A3: 46209 | B3: DM75893663 | C3: 加護病房設備室內定位系統建置案 | D3: 1 | E3: 588000 | F3: =D3*E3 -> 588000 | G3: 115/07/28 | H3: AE1150705468 | I3: 第一期
A4: 46231 | B4: DP13770703 | C4: AI排班與加班預測系統採購案-簽約訂金 | D4: 1 | E4: 1071000 | F4: =D4*E4 -> 1071000 | G4: 115/08/04 | H4: AE1150800126 | I4: 簽約訂金
A5: 46231 | B5: DP13770704 | C5: AI排班與加班預測系統採購案-第一階段 | D5: 1 | E5: 714000 | F5: =D5*E5 -> 714000 | G5: 115/08/04 | H5: AE1150800126 | I5: 第一階段
A6: 46231 | B6: DP13770705 | C6: AI排班與加班預測系統採購案-第二階段 | D6: 1 | E6: 1071000 | F6: =D6*E6 -> 1071000 | G6: 115/08/04 | H6: AE1150800126 | I6: 第二階段
A7: 46289 | B7: FR24777851 | C7: AI排班與加班預測系統採購案-第三階段(尾款) | D7: 1 | E7: 714000 | F7: =D7*E7 -> 714000 | G7: 115/10/13 | H7: AE1151002157 | I7: 第三階段
A9: 總計 | F9: =SUM(F3:F8) -> 4158000

Sheet 業務費總表
A1: 範疇 | B1: 項目 | C1: 預算金額 (A) | D1: 已核銷支出 (B) | E1: 剩餘可用餘額 (C) | F1: 執行進度 (%)
A2: 範疇一 | B2: 餐費 | C2: 130000 | D2: =SUMIF('明細表 '!B:B, B2, '明細表 '!D:D) -> 62838 | E2: =C2-D2 -> 67162 | F2: =D2/C2 -> 0.48336923
B3: 文具紙張 | C3: 7000 | D3: =SUMIF('明細表 '!B:B, B3, '明細表 '!D:D) -> 6991 | E3: =C3-D3 -> 9 | F3: =D3/C3 -> 0.99871429
B4: 印刷 | C4: 10000 | D4: =SUMIF('明細表 '!B:B, B4, '明細表 '!D:D) -> 1525 | E4: =C4-D4 -> 8475 | F4: =D4/C4 -> 0.1525
B5: 雜支費 | C5: 20000 | D5: =SUMIF('明細表 '!B:B, B5, '明細表 '!D:D) -> 19831 | E5: =C5-D5 -> 169 | F5: =D5/C5 -> 0.99155
B6: 出席費 | C6: 90000 | D6: =SUMIF('明細表 '!B:B, B6, '明細表 '!D:D) -> 65000 | E6: =C6-D6 -> 25000 | F6: =D6/C6 -> 0.72222222 | G6: =SUM(D5,D2) -> 82669
B7: 國內旅費 | C7: 4200 | D7: =SUMIF('明細表 '!B:B, B7, '明細表 '!D:D) -> 4200 | E7: =C7-D7 -> 0 | F7: =D7/C7 -> 1
A8: 合計 | C8: =SUM(C2:C7) -> 261200 | D8: =SUM(D2:D7) -> 160385 | E8: =C8-D8 -> 100815 | F8: =D8/C8 -> 0.61403139
A9: 利用餐費沖帳核銷 | C9: 待沖帳金額 | D9: 已沖帳 | E9: 剩餘
C10: =SUMIF('明細表 '!B:B, "待沖帳", '明細表 '!D:D) -> 51128 | D10: =SUM('明細表 '!E:E) -> 49608 | E10: =(C10-D10) -> 1520
B12: 日期 | C12: 項目 | D12: 費用 | E12: 剩餘可用餘額 (C) | F12: 已用$(備註)
B13: 2026/4/15計 | C13: 還科室經費 | D13: 27000 | F13: 扣除第一次出席費 14500
C14: 已借支 (餐費+雜支) | D14: 65000 | E14: =E2+E5 -> 67331 | F14: =D14-E14 -> -2331
B15: 46134 | C15: 借科室經費 (出席費) | D15: 20000 | F15: 用大計畫核銷還款 AE1150403576 AE1150403577
B16: 46140 | C16: 借科室經費 (出席費) | D16: 7500 | F16: 用大計畫核銷還款 AE1150403584
B17: 46157 | C17: 借科室經費 (飲料費) | D17: 1152
B18: 46163 | C18: 借科室經費 (便當+飲料) | D18: 3000 | F18: 審查會前會 石蜜園 雞腿便當*15 50嵐*15
B19: 46164 | C19: 借科室經費 (出席費) | D19: 5000
B20: 46164 | C20: 借科室經費 (餐費) | D20: 3300 | F20: 餐盒費用
C21: 總計借款 | D21: =SUM(D15:D20,D13) -> 66952
C22: 借款扣除出席費 | D22: =SUM(D20,D18,D17,D13)-12500 -> 21952
B23: 46167 | C23: 還科室經費 | D23: 19452 | E23: 不算總出席費 1.15000 2.20000 3.7500 4.5000
C24: 已支出 (餐費+雜支) | D24: =SUM(D2,D5) -> 82669
B25: 46184 | C25: 借科室經費 (出席費) | D25: 20000

Sheet 明細表 
A1: 發票/收據日期 | B1: 會計核銷科目 | C1: 實際購買品項 | D1: 核銷總額 | E1: 可沖帳額度 | F1: 實際支出 | G1: 代墊 / 借支人員 | H1: 自科室借款 | I1: 還款狀態 | J1: 核銷單 列印日期 | K1: 核銷案號 (黃底未借支)
A2: 46058 | B2: 雜支費 | C2: 小組會議飲料 | D2: =F2+E2 -> 1241 | E2: 0 | F2: 1241 | G2: 洪郁涵 | I2: V | J2: 115/03/24 | K2: AE1150302061
A3: 46058 | B3: 餐費 | C3: 小組會議便當 | D3: =F3+E3 -> 1430 | E3: 0 | F3: 1430 | G3: 洪郁涵 | I3: V | J3: 115/03/18 | K3: AE1150301293
A4: 46106 | B4: 餐費 | C4: 小組會議便當 | D4: =F4+E4 -> 1260 | E4: 0 | F4: 1260 | J4: 115/04/16 | K4: AE1150401525
A5: 46106 | B5: 雜支費 | C5: 小組會議飲料 | D5: =F5+E5 -> 932 | E5: 0 | F5: 932 | G5: 科室借款 | H5: 2192 | I5: V | J5: 115/04/16 | K5: AE1150401528
A6: 46107 | B6: 雜支費 | C6: AI排班評選會咖啡 | D6: =F6+E6 -> 2076 | E6: 0 | F6: 2076 | G6: 科室借款 | H6: 2076 | I6: V | J6: 115/04/16 | K6: AE1150401511
A7: 46107 | B7: 出席費 | C7: AI排班評選會委員出席費 | D7: =F7+E7 -> 12500 | E7: 0 | F7: 12500 | G7: 科室借款 | H7: 15000 | I7: V | J7: 115/04/28 | K7: AE1150401513
A8: 46111 | B8: 餐費 | C8: 小組會議便當 | D8: =F8+E8 -> 1890 | E8: 0 | F8: 1890 | J8: 115/04/16 | K8: AE1150401518
A9: 46111 | B9: 雜支費 | C9: 小組會議飲料 | D9: =F9+E9 -> 910 | E9: 0 | F9: 910 | G9: 科室借款 | H9: 2800 | I9: V | J9: 115/04/16 | K9: AE1150401519
A10: 46120 | B10: 代墊還款 | C10: 小組會議飲料 | D10: =F10+E10 -> 1106 | E10: 0 | F10: 1106
A11: 46121 | B11: 雜支費 | C11: 小組會議飲料 | D11: =F11+E11 -> 95 | E11: 0 | F11: 95 | J11: 115/04/28 | K11: AE1150403373
A12: 46122 | B12: 餐費 | C12: 小組會議便當 | D12: =F12+E12 -> 2430 | E12: 0 | F12: 2430 | G12: 科室借款 | H12: 3511 | I12: V | J12: 115/04/17 | K12: AE1150401670
A13: 46126 | B13: 雜支費 | C13: 小組會議飲料 | D13: =F13+E13 -> 616 | E13: 0 | F13: 616 | J13: 115/04/16 | K13: AE1150401522
A14: 46126 | B14: 雜支費 | C14: 小組會議飲料 | D14: =F14+E14 -> 135 | E14: 0 | F14: 135 | G14: 科室借款 | H14: 751 | I14: V | J14: 115/04/16 | K14: AE1150401522
A15: 46134 | B15: 雜支費 | C15: 採購案討論會議飲料 | D15: =F15+E15 -> 1480 | E15: 0 | F15: 1480 | G15: 張久大 | I15: V | J15: 115/04/30 | K15: AE1150403551
A16: 46135 | B16: 出席費 | C16: AI排班 出席費 (轉)洪郁涵 | D16: =F16+E16 -> 10000 | E16: 0 | F16: 10000 | G16: 科室借款 | H16: =SUM(H2:H14) -> 26330 | I16: V | J16: 115/04/30 | K16: AE1150403576
A17: 46135 | B17: 出席費 | C17: 加護病房 出席費 (轉)洪郁涵 | D17: =F17+E17 -> 10000 | E17: 0 | F17: 10000 | G17: 科室借款 | I17: V | J17: 115/04/30 | K17: AE1150403577
A18: 46135 | B18: 雜支費 | C18: 採購評選會咖啡 | D18: =F18+E18 -> 2300 | E18: 0 | F18: 2300 | G18: 張久大 | I18: V | J18: 115/04/30 | K18: AE1150403559
A19: 46133 | B19: 印刷 | C19: 海報輸出 | D19: =F19+E19 -> 330 | E19: 0 | F19: 330 | G19: 何承翰 | J19: 115/04/30 | K19: AE1150403563
A20: 46135 | B20: 印刷 | C20: 海報輸出 | D20: =F20+E20 -> 160 | E20: 0 | F20: 160 | G20: 何承翰 | J20: 115/04/30 | K20: AE1150403566
A21: 46136 | B21: 印刷 | C21: 彩印 | D21: =F21+E21 -> 1035 | E21: 0 | F21: 1035 | G21: 何承翰 | J21: 115/04/30 | K21: AE1150403570
A22: 46141 | B22: 雜支費 | C22: 審查會前會飲料 | D22: =F22+E22 -> 3351 | E22: 0 | F22: 3351 | G22: 王喻萱 | I22: V | J22: 115/04/30 | K22: AE1150403555
A23: 46142 | B23: 出席費 | C23: ERP審查會出席費 | D23: =F23+E23 -> 7500 | E23: 0 | F23: 7500 | G23: 科室借款 | I23: V | J23: 115/04/30 | K23: AE1150403584
A24: 46142 | B24: 雜支費 | C24: 審查會咖啡 | D24: =F24+E24 -> 2893 | E24: 0 | F24: 2893 | G24: 王喻萱 | I24: V | J24: 115/04/30 | K24: AE1150403587
A25: 46134 | B25: 文具紙張 | C25: 不留痕雙面膠 (轉)何承翰 | D25: =F25+E25 -> 75 | E25: 0 | F25: 75 | G25: 何承翰 | J25: 115/04/30 | K25: AE1150403593
A26: 46136 | B26: 雜支費 | C26: 籤筒用品 (轉)何承翰 | D26: =F26+E26 -> 114 | E26: 0 | F26: 114 | G26: 何承翰 | J26: 115/04/30 | K26: AE1150403594
A27: 46141 | B27: 雜支費 | C27: 海報看板(畫板) | D27: =F27+E27 -> 899 | E27: 0 | F27: 899 | G27: 何承翰 | J27: 115/04/30 | K27: AE1150403596
A28: 46141 | B28: 文具紙張 | C28: 丹麥夾、事務盤 (轉)何承翰 | D28: =F28+E28 -> 136 | E28: 0 | F28: 136 | G28: 何承翰 | K28: AE1150503073
A29: 46146 | B29: 文具紙張 | C29: 審查會文具 (轉)何承翰 | D29: =F29+E29 -> 4813 | E29: 0 | F29: 4813 | G29: 何承翰 | J29: 115/05/04 | K29: AE1150500192
A30: 46157 | B30: 代墊還款 | C30: 小組會議飲料 | D30: =F30+E30 -> 1152 | E30: 0 | F30: 1152 | G30: 科室借款 | I30: V
A31: 46157 | B31: 餐費 | C31: 第7次執行會議便當 4/8:1106+5/15:1152+35 | D31: =F31+E31 -> 2293 | E31: 0 | F31: 2293 | G31: 王喻萱 | I31: V | J31: 115/05/15 | K31: AE1150501487
A32: 46163 | B32: 餐費 | C32: 石蜜園便當 | D32: =F32+E32 -> 2155 | E32: 0 | F32: 2155 | J32: 115/05/26 | K32: AE1150503124
A33: 46163 | B33: 待沖帳 | C33: 50嵐飲料 | D33: =F33+E33 -> 839 | E33: 0 | F33: 839
A34: 46164 | B34: 雜支費 | C34: 評選/審查會咖啡 | D34: =F34+E34 -> 2789 | E34: 0 | F34: 2789 | G34: 王喻萱 | I34: V | J34: 115/05/26 | K34: AE1150503075
A35: 46164 | B35: 待沖帳 | C35: 審查會餐盒 | D35: =F35+E35 -> 3300 | E35: 0 | F35: 3300
A36: 46164 | B36: 出席費 | C36: 手術排程審查會出席費 (轉)洪郁涵 | D36: =F36+E36 -> 5000 | E36: 0 | F36: 5000 | G36: 科室借款 | I36: V | J36: 115/05/26 | K36: AE1150503077
A37: 46167 | B37: 代墊還款 | C37: 還喻萱代墊款 | D37: =F37+E37 -> -9068 | E37: 0 | F37: -9068 | I37: V
A38: 46167 | B38: 代墊還款 | C38: 還科室經費 | D38: =F38+E38 -> -19452 | E38: 0 | F38: -19452 | I38: V
A39: 46168 | B39: 代墊還款 | C39: 還久大代墊款 | D39: =F39+E39 -> -3780 | E39: 0 | F39: -3780 | I39: V
A40: 46169 | B40: 待沖帳 | C40: 咖啡禮盒(4.30) | D40: =F40+E40 -> 5460 | E40: 0 | F40: 5460 | G40: 林孟蓁A10489 | I40: V
...

Sheet 業務費-租金
A1: 業務費-租金款項
A2: 發票開立日期 | B2: 發票號碼 | C2: 品名 | D2: 數量 | E2: 單價 | F2: 總計 (含稅) | G2: 核銷單列印日期 | H2: 核銷案號 | I2: 說明 / 備註
A3: 46240 | B3: DM69219420 | C3: 7月租金-手術智慧排程與管理系統 | D3: 1 | E3: 21454 | F3: 22527 | G3: 115/08/11 | H3: AE1150801425
A4: 46255 | B4: DM69219437 | C4: 8月租金-手術智慧排程與管理系統 | D4: 1 | E4: 349167 | F4: =E4*D4 -> 349167 | G4: 115/08/25 | H4: AE1150802459
A8: 總計 | F8: =SUM(F3:F7) -> 371694

Sheet 業務費-人事費
A1: 業務費-人事費
A2: 日期 | B2: 項目 | C2: 總計 | D2: 核銷單列印日期 | E2: 核銷案號 | F2: 說明 / 備註
A3: 46112 | B3: 研究助理3月薪資 | C3: 27231
A4: 46142 | B4: 研究助理4月薪資 | C4: 36893
A5: 46171 | B5: 研究助理5月薪資 | C5: 37897
A6: 46203 | B6: 研究助理6月薪資 | C6: 37897
A7: 46203 | B7: 研究助理6月三節獎金 | C7: 4834
A8: 46234 | B8: 研究助理7月薪資 | C8: 37897
A9: 46265 | B9: 研究助理8月薪資 | C9: 37897
A10: 46295 | B10: 研究助理9月薪資 | C10: 37897
A11: 總計 | C11: =SUM(C3:C10) -> 258443

Sheet 交通費
A1: 發票/收據日期 | B1: 項目 | C1: 支出金額 | D1: 說明 / 備註 | E1: 自科室借款 | F1: 核銷案號
A2: 2026.03.26 | B2: 交通費 | C2: 385 | D2: 3/26評選會委員交通費 | F2: AE1150500416
A3: 2026.03.26 | B3: 交通費 | C3: 445 | D3: 3/26評選會委員交通費 | F3: AE1150601718
A4: 2026.06.11 | B4: 交通費 | C4: 375 | D4: 6/11評選會委員交通費 | F4: AE1150601720
A5: 2026.06.11 | B5: 交通費 | C5: 350 | D5: 6/11評選會委員交通費
A6: 2026.06.12 | B6: 交通費 | C6: 370 | D6: 6/12評選會委員交通費 | F6: AE1150601723

Sheet 參數設定
A1: 會計核銷科目
A2: 餐費 | B2: 評選/審查會咖啡
A3: 文具紙張 | B3: 小組會議便當
A4: 印刷 | B4: 小組會議飲料
A5: 雜支費 | B5: 海報輸出
A6: 出席費 | B6: 彩印
A7: 租金 | B7: 其他
A8: 國內旅費
A9: 待沖帳
A10: 代墊款
